Workbook

Sheet Sheet1
A1: Timestamp | B1: Please enter your Prolific ID: | C1: What is your age? (in years) | D1: What is your gender? | E1: What is your highest attained education level? | F1: What is/are your native language(s) | G1: What other languages do you speak? | H1: My fluency in English: | I1: You can comprehend and understand information you read in English? | J1: When I read, I often read in: | K1: What types of materials do you prefer to read in English: | L1: What is your level of comfort understanding complex texts in English? | M1: What is your reading speed when reading texts in English? | N1: When using the telephone, do you get the numbers mixed up when you dial? | O1: Is your spelling poor? | P1: When writing down dates, do you often make mistakes? | Q1: Do you mix up dates and times and miss appointments? | R1: Do you find forms difficult and confusing? | S1: Do you find it difficult to take messages on the phone and pass them on correctly? | T1: Do you mix up bus numbers like 35 and 53? | U1: Do you find it difficult to say the months of the year forwards in a fluent manner? | V1: When you were at school, did you find it hard to learn the multiplication or times tables? | W1: Do you take longer than you should to read a page of a book? | X1: Do you find difficulty in telling left from right? | Y1: Did you find it difficult to decide how to answer these questions? | Z1: Describe how your reading habits changed over time? | AA1: Have you ever been diagnosed with Dyslexia? | AB1: It is challenging for you to read something you have little to no interest in. | AC1: Have you ever been diagnosed with a reading or learning disability (e.g., dyslexia)? If yes, which one and how long ago? | AD1: Have you ever been diagnosed with ADD/ADHD? If yes, which one/s and how long ago? | AE1: Have you ever been diagnosed with any medical and neurological conditions (macular degeneration, diabetes, memory disorders, LPD, dyspraxia, etc...) If yes, which one/s and how long ago? | AF1: Are you currently under the influence of any drugs, medications, alcohol, or other stimulants (e.g., caffeine, nicotine) that may affect reading/attention? If yes, which? | AG1: Do you have normal or corrected vision? | AH1: If your vision is corrected, how was it corrected (glasses, lenses, surgery, etc.)? | AI1: Which device are you using right now to participate in this study? | AJ1: Please describe your current surroundings. For example, are you indoors/outside, by a window, under natural or artificial light, is the room light/dark, is the room small/large? | AK1: When you submit your response, the link to the main study will be in the next page. | AM1: dys_score_shaun
A2: 45847.46 | B2: xxxx | C2: 25 | D2: Male | E2: Master's degree | F2: Other | G2: Albanian | H2: 5 | I2: 5 | J2: English | K2: Books, Online articles, Social media | L2: 5 | M2: 3 | N2: No | O2: No | P2: No | Q2: No | R2: No | S2: No | T2: No | U2: No | V2: No | W2: No | X2: No | Y2: No | Z2: Because of ADHD, i interrupt myself many times while reading, and get back to it | AA2: No | AB2: 4 | AC2: NO | AD2: Yes, not sure how long ago, I've had ADHD for as long as I can remember | AE2: no | AF2: no | AG2: Yes | AH2: Surgery | AI2: Laptop | AJ2: Indoors, artificial light, light room, large room
A3: 45848.509 | B3: 666559e634fffd1ce19ba654 | C3: 30 | D3: female | E3: Bachelor's Degree (4-years of college) | F3: English | H3: 5 | I3: 5 | J3: English | K3: Books, Online articles, Social media | L3: 5 | M3: 4 | N3: No | O3: No | P3: No | Q3: Yes | R3: No | S3: No | T3: No | U3: No | V3: No | W3: Yes | X3: No | Y3: No | Z3: I read slower as I've gotten older | AA3: No | AB3: 5 | AC3: ADHD | AD3: Yes, in 2019 | AE3: No | AF3: Yes, Adderall | AG3: Yes | AH3: Glasses | AI3: Laptop | AJ3: Indoors, in my bedroom, artificial light, small room | AK3: I understand
A4: 45848.511 | B4: 5da8edc60f9c9c0017526948 | C4: 35 | D4: Male | E4: Associate's degree (2-years of college) | F4: English | H4: 5 | I4: 5 | J4: English | K4: Books, Magazines, Newspapers, Online articles, Social media | L4: 4 | M4: 4 | N4: No | O4: No | P4: No | Q4: No | R4: No | S4: No | T4: No | U4: No | V4: No | W4: No | X4: No | Y4: No | Z4: I feel I am reading less or more short form content over long form. | AA4: No | AB4: 4 | AC4: Autism | AD4: No | AE4: No | AF4: No | AG4: Yes | AH4: Glasses | AI4: Laptop | AJ4: I am indoors by a large window under natural light and the room is small. It contains clothing one door two lamps a desktop, desk, monitor, dresser and power strip. | AK4: I understand
A5: 45848.513 | B5: 614e0468bbbac16be38fa13f | C5: 50 | D5: Male | E5: Associate's degree (2-years of college) | F5: English | H5: 5 | I5: 5 | J5: English | K5: Books, Magazines, Newspapers, Online articles, Social media | L5: 5 | M5: 5 | N5: Yes | O5: Yes | P5: No | Q5: No | R5: No | S5: No | T5: No | U5: No | V5: Yes | W5: Yes | X5: Yes | Y5: Yes | Z5: i dont read paper books I prefer to stick to electronic readers | AA5: No | AB5: 5 | AC5: yes in 3rd grade in school but not diagnosed by a dr | AD5: not by a dr but I suspect I have ADHD | AE5: Diabetes | AF5: caffeine | AG5: Yes | AH5: surgery | AI5: Laptop | AJ5: indoors office | AK5: I understand
A6: 45848.514 | B6: 63d1125c54e8148f4cd30a65 | C6: 61 | D6: Male | E6: Bachelor's Degree (4-years of college) | F6: English | G6: Welsh | H6: 5 | I6: 5 | J6: English | K6: Books, Newspapers, Online articles, Social media | L6: 5 | M6: 4 | N6: No | O6: Yes | P6: No | Q6: No | R6: No | S6: No | T6: No | U6: No | V6: No | W6: No | X6: No | Y6: No | Z6: I read more non fiction books | AA6: No | AB6: 4 | AC6: No | AD6: No | AE6: No | AF6: No | AG6: Yes | AH6: Glasses/contact lenses | AI6: Laptop | AJ6: I am in a campervan which is my office for today. It is sunny and warm outside | AK6: I understand
A7: 45853.835 | B7: 6664d3b710bb2abd191e1b64 | C7: 47 | D7: Female | E7: Bachelor's Degree (4-years of college) | F7: English | H7: 5 | I7: 5 | J7: English | K7: Books, Magazines, Newspapers, Online articles, Social media | L7: 4 | M7: 4 | N7: No | O7: No | P7: No | Q7: No | R7: No | S7: No | T7: No | U7: No | V7: No | W7: No | X7: No | Y7: No | Z7: I don't read for pleasure as much as I did when I was younger. I don't have as much free time as I did back then. I've also replaced the habit of reading with scrolling social media. | AA7: No | AB7: 5 | AC7: No | AD7: Yes, I have ADD. I was diagnosed about 20 years ago. | AE7: No | AF7: No | AG7: Yes | AH7: Glasses | AI7: Laptop | AJ7: I am currently inside my home. I am in my bedroom using artificial light. It is a fairly large room. | AK7: I understand
A8: 45853.839 | B8: 676cf85a261dedbddea3e240 | C8: 51 | D8: female | E8: Master's degree | F8: English | H8: 5 | I8: 5 | J8: English | K8: Books, Magazines, Newspapers, Online articles, Social media | L8: 5 | M8: 5 | N8: No | O8: No | P8: No | Q8: No | R8: No | S8: No | T8: No | U8: No | V8: No | W8: No | X8: No | Y8: No | Z8: I would say I read more complex books-more complex subjects | AA8: No | AB8: 4 | AC8: no | AD8: no | AE8: no | AF8: no | AG8: Yes | AH8: glasses | AI8: Laptop | AJ8: indoors on my living room by natural lit window | AK8: I understand
A9: 45853.85 | B9: 668a9e53e7690b3b64d48e92 | C9: 46 | D9: male | E9: Bachelor's Degree (4-years of college) | F9: English | G9: Urdu | H9: 5 | I9: 5 | J9: English | K9: Online articles | L9: 4 | M9: 4 | N9: No | O9: No | P9: No | Q9: No | R9: No | S9: No | T9: No | U9: No | V9: No | W9: No | X9: No | Y9: No | Z9: When I was younger, I mostly read fiction - especially fantasy and adventure novels. As I got older, I started shifting more toward non-fiction, particularly books on psychology, productivity, and personal finance. These days, I do a mix of both, but I read shorter articles or online content more often than full-length books due to time constraints. I also listen to audiobooks or podcasts now, which wasn’t something I used to do. | AA9: No | AB9: 4 | AC9: no | AD9: no | AG9: Yes | AH9: laser surgery plus YAG laser | AI9: Laptop | AJ9: indoors in the living room under artificial light, the room is large and spacious. | AK9: I understand
A10: 45853.857 | B10: 610508c09d61c098f072605b | C10: 28 | D10: Female | E10: Bachelor's Degree (4-years of college) | F10: English | H10: 5 | I10: 5 | J10: English | K10: Books, Magazines, Newspapers, Online articles, Social media | L10: 5 | M10: 5 | N10: No | O10: No | P10: No | Q10: No | R10: No | S10: No | T10: No | U10: No | V10: No | W10: No | X10: No | Y10: No | Z10: They have remained the same | AA10: No | AB10: 2 | AG10: Yes | AH10: glasses | AI10: Laptop | AJ10: Indoors, bed room, artificial lighting. | AK10: I understand
A11: 45853.877 | B11: 65ee224fc6146bbd065a8ae0 | C11: 24 | D11: female | E11: Bachelor's Degree (4-years of college) | F11: English | H11: 5 | I11: 5 | J11: English | K11: Books, Magazines, Newspapers, Online articles, Social media | L11: 5 | M11: 5 | N11: No | O11: No | P11: No | Q11: No | R11: No | S11: No | T11: No | U11: No | V11: No | W11: No | X11: No | Y11: No | Z11: When I was younger I read books all the time. I would finish mini chapters books in a couple hours. When I was a teen, I stopped reading for a while unless it was necessary for school. But since I have graduated college, I now enjoy reading books for pleasure again! | AA11: No | AB11: 4 | AC11: No | AD11: No | AE11: No | AF11: No | AG11: Yes | AH11: contact lenses | AI11: Laptop | AJ11: inside with the light on right above me. The room is smaller - it is my bedroom. | AK11: I understand
A12: 45855.656 | B12: 66eddcfe67e927db6f0a4768 | C12: 37 | D12: nonbinary | E12: Bachelor's Degree (4-years of college) | F12: English | H12: 5 | I12: 5 | J12: English | K12: Books, Magazines, Newspapers, Online articles, Social media | L12: 4 | M12: 4 | N12: Yes | O12: No | P12: No | Q12: No | R12: Yes | S12: Yes | T12: Yes | U12: No | V12: No | W12: No | X12: No | Y12: No | Z12: I read a little bit less than I used to nowadays, but I do spend a lot of my time engaging with written posts and fanfiction and news articles. | AA12: No | AB12: 4 | AC12: No | AD12: No | AE12: No | AF12: No | AG12: Yes | AH12: glasses | AI12: Laptop | AJ12: I am inside, sitting on my couch, and my son is in his room watching stuff on tiktok. | AK12: I understand
A13: 45855.658 | B13: 6108295fdd0270d7544b5a8a | C13: 35 | E13: Master's degree | F13: English | H13: 5 | I13: 5 | J13: English | K13: Books, Magazines, Newspapers, Online articles | L13: 5 | M13: 4 | N13: Yes | O13: Yes | P13: Yes | Q13: Yes | R13: Yes | S13: Yes | T13: Yes | U13: Yes | V13: Yes | W13: No | X13: Yes | Y13: Yes | Z13: I have switched to reading more ebooks than physical because I like that I can customize things like font and spacing | AA13: No | AB13: 4 | AC13: diagnosed with ADHD about 6 years ago. never tested for dyslexia but suspect I have it | AD13: yes, ADHD inatentive type about 6 years ago | AE13: migraines 21 years ago and autism 11 years ago | AF13: caffiene from coffee (used to self-medicate ADHD) | AG13: Yes | AH13: glasses for distance; nothing needed for close up | AI13: Laptop | AJ13: indoors in small living room, window curtains open behind me but closed in front of me, no artificial lights exept pc screen, slightly dim room | AK13: I understand
A14: 45855.659 | B14: 67842c60c9cba1e154a69bbd | C14: 41 | D14: Male | E14: Master's degree | F14: English | H14: 5 | I14: 5 | J14: English | K14: Books, Magazines, Newspapers, Online articles, Social media | L14: 5 | M14: 5 | N14: Yes | O14: No | P14: No | Q14: Yes | R14: No | S14: No | T14: Yes | U14: Yes | V14: Yes | W14: Yes | X14: No | Y14: No | Z14: It always consistent. | AA14: No | AB14: 3 | AC14: No | AD14: No | AE14: No | AF14: No | AG14: Yes | AI14: Desktop | AJ14: My room is too quiet there is no one around me. | AK14: I understand
A15: 45855.66 | B15: 67e99ec5ac9317593a3fd76b | C15: 31 | D15: male | E15: Bachelor's Degree (4-years of college) | F15: English | H15: 5 | I15: 4 | J15: English | K15: Books | L15: 4 | M15: 4 | N15: No | O15: No | P15: No | Q15: No | R15: No | S15: No | T15: No | U15: No | V15: No | W15: No | X15: No | Y15: No | Z15: nothing has changed | AA15: No | AB15: 3 | AD15: 4yrs | AF15: yes | AG15: No | AI15: Laptop | AJ15: indoors | AK15: I understand
A16: 45855.661 | B16: 67e08140fcb66593f11b6e8e | C16: 32 | D16: male | E16: Bachelor's Degree (4-years of college) | F16: English | H16: 5 | I16: 5 | J16: English | K16: Books, Magazines, Newspapers, Online articles, Social media | L16: 4 | M16: 4 | N16: No | O16: No | P16: Yes | Q16: No | R16: No | S16: No | T16: No | U16: No | V16: Yes | W16: No | X16: No | Y16: No | Z16: it increased over time due to my consistency | AA16: No | AB16: 5 | AC16: no | AD16: no | AE16: no | AF16: no | AG16: No | AI16: Laptop | AJ16: i am indoors facing my door | AK16: I understand
A17: 45855.662 | B17: 67ce1065642e75fb03792cd2 | C17: 48 | E17: Master's degree | F17: English | H17: 5 | I17: 5 | J17: English | K17: Books, Magazines, Newspapers, Online articles, Social media | L17: 5 | M17: 5 | N17: No | O17: No | P17: No | Q17: No | R17: Yes | S17: No | T17: Yes | U17: Yes | V17: No | W17: No | X17: No | Y17: No | Z17: i involved myself on article readin mostly | AA17: No | AB17: 4 | AG17: Yes | AI17: Desktop | AJ17: i am in a room full light | AK17: I understand
A18: 45855.664 | B18: 6578d3429b81c0b73ac4e719 | C18: 22 | D18: Female | E18: Some college | F18: English | G18: Spanish | H18: 5 | I18: 5 | J18: English | K18: Books, Magazines, Newspapers, Online articles, Social media | L18: 4 | M18: 4 | N18: Yes | O18: Yes | P18: Yes | Q18: Yes | R18: Yes | S18: Yes | T18: Yes | U18: No | V18: No | W18: No | X18: Yes | Y18: Yes | Z18: Ive become a faster reader | AA18: No | AB18: 5 | AC18: no | AD18: Yes, Last october i was diagnosed with ADHD | AE18: no | AF18: caffine | AG18: Yes | AH18: contact lenses | AI18: Laptop | AJ18: indoors in a brightly lit room | AK18: I understand
A19: 45855.667 | B19: 60d8c6bc9686529cdc824a49 | C19: 39 | D19: Female | E19: High school/GED | F19: English | H19: 5 | I19: 5 | J19: English | K19: Books, Magazines, Newspapers, Online articles, Social media | L19: 4 | M19: 4 | N19: Yes | O19: Yes | P19: Yes | Q19: No | R19: Yes | S19: No | T19: Yes | U19: No | V19: Yes | W19: Yes | X19: Yes | Y19: Yes | Z19: I've noticed that I think I am more dyslexic | AA19: No | AB19: 5 | AC19: No, but I do remember when I was in 7th grade I had to stay after school with my reading teacher for most of the year because I was at least 3 levels behind where I needed to be. I don't know why I wasn't taken to the doctors about it because my parents knew about it. | AD19: No, but I recently told my husband that I am going to talk to my doctor about it when I go next. | AE19: no | AF19: No | AG19: Yes | AH19: glasses | AI19: Desktop | AJ19: indoor, in front of windows that the blinds are closed. sitting at my desk. | AK19: I understand
A20: 45855.667 | B20: 67acea60283b9ad009444b49 | C20: 29 | D20: Female | E20: Bachelor's Degree (4-years of college) | F20: English | H20: 5 | I20: 5 | J20: English | K20: Books, Magazines, Newspapers, Online articles, Social media | L20: 5 | M20: 5 | N20: No | O20: No | P20: No | Q20: No | R20: No | S20: No | T20: No | U20: Yes | V20: No | W20: No | X20: No | Y20: No | Z20: They've improved. | AA20: No | AB20: 3 | AG20: No | AI20: Desktop | AJ20: Indoors, medium to darker room, large room | AK20: I understand
A21: 45855.669 | B21: 67d232491fcc58c4a4519aef | C21: 31 | D21: Female | E21: Bachelor's Degree (4-years of college) | F21: English | H21: 5 | I21: 5 | J21: English | K21: Books, Magazines, Newspapers, Online articles, Social media | L21: 5 | M21: 5 | N21: No | O21: No | P21: No | Q21: No | R21: No | S21: No | T21: No | U21: No | V21: No | W21: No | X21: No | Y21: No | Z21: no stress in reading and made it so fun in reading | AA21: Yes | AB21: 4 | AC21: Dyslexia, 15 years ago | AD21: ADHD , 15 years ago | AE21: none | AF21: none | AG21: Yes | AH21: normal | AI21: Laptop | AJ21: indoors in a quiet room | AK21: I understand
A22: 45855.671 | B22: 615110f7e86a1185ccf25ce9 | C22: 61 | D22: female | E22: Associate's degree (2-years of college) | F22: English | H22: 5 | I22: 5 | J22: English | K22: Books, Magazines, Newspapers, Online articles, Social media | L22: 5 | M22: 4 | N22: Yes | O22: Yes | P22: Yes | Q22: No | R22: No | S22: No | T22: No | U22: No | V22: No | W22: No | X22: No | Y22: No | Z22: I read books, then the computer, then my phone..still read all of them | AA22: Yes | AB22: 3 | AC22: Dyslexia, in grade school, but was taught how to get around it, | AD22: no | AE22: diabetes 2020 | AF22: no | AG22: Yes | AH22: glasses | AI22: Desktop | AJ22: in my house in the school room, on the computer buy the window with lighting from both it and lamp, room is medium size | AK22: I understand
A23: 45855.689 | B23: 5dd3699ee73e6136c640f1cf | C23: 48 | D23: male | E23: Bachelor's Degree (4-years of college) | F23: English | H23: 5 | I23: 5 | J23: English | K23: Books, Magazines, Newspapers, Online articles, Social media | L23: 5 | M23: 5 | N23: No | O23: No | P23: No | Q23: No | R23: No | S23: No | T23: No | U23: No | V23: No | W23: No | X23: No | Y23: No | Z23: Over time, my reading habits have shifted from mostly fiction and leisurely reading in childhood to more non-fiction, news, and professional materials as I’ve grown older; now I prioritize purpose-driven reading—focused on learning, staying informed, or personal development—though I still enjoy the occasional novel when time allows | AA23: No | AB23: 1 | AC23: no | AD23: no | AE23: no | AF23: no | AG23: No | AH23: n/a | AI23: Laptop | AJ23: I am indoors in a moderately sized room, lit primarily by artificial light. There’s a window nearby letting in some natural light, but it’s not the main source of illumination. The space feels quiet and organized, with a neutral ambiance that’s suitable for focused work. | AK23: I understand
A24: 45855.709 | B24: 67062295123561f8241f65fc | C24: 29 | D24: Male | E24: High school/GED | F24: English | H24: 5 | I24: 5 | J24: English | K24: Books, Magazines, Newspapers, Online articles, Social media | L24: 5 | M24: 3 | N24: Yes | O24: Yes | P24: Yes | Q24: No | R24: Yes | S24: No | T24: Yes | U24: Yes | V24: No | W24: Yes | X24: Yes | Y24: No | Z24: As a kid it was all about getting the gist of what was written and filling in the blanks. Now I have a much or mithodical approach. But I still have to fill in the gaps or reread the sentence once or twice. | AA24: No | AB24: 5 | AG24: Yes | AI24: Laptop | AJ24: I am indoors, with a mix of natural and artificial light. It's a smallish room. | AK24: I understand
A25: 45856.438 | B25: 5fa883c9bd81737431af4d49 | C25: 36 | D25: female | E25: High school/GED | F25: English | H25: 5 | I25: 5 | J25: English | K25: Books, Magazines, Social media | L25: 5 | M25: 3 | N25: Yes | O25: No | P25: Yes | Q25: No | R25: Yes | S25: No | T25: Yes | U25: No | V25: Yes | W25: Yes | X25: Yes | Y25: No | Z25: i've not really noticed any changes | AA25: Yes | AB25: 5 | AC25: dyslexia - since i was a child | AD25: n/a | AE25: n/a | AF25: caffeine, alcohol | AG25: Yes | AI25: Desktop | AJ25: inside with a mix of natural and artificial light | AK25: I understand
A26: 45856.448 | B26: 67dde901251834ece323f258 | C26: 36 | D26: Transwoman | E26: Master's degree | F26: English | H26: 5 | I26: 5 | J26: English | K26: Books, Magazines, Online articles, Social media | L26: 5 | M26: 5 | N26: No | O26: No | P26: No | Q26: No | R26: No | S26: No | T26: No | U26: No | V26: No | W26: No | X26: No | Y26: No | Z26: I read daily | AA26: Yes | AB26: 4 | AG26: No | AI26: Laptop | AJ26: indoors currently in the living room | AK26: I understand
A27: 45856.451 | B27: 67e469d0bbb689eacffa0ee0 | C27: 34 | D27: transgender | E27: Master's degree | F27: English | H27: 4 | I27: 4 | J27: English | K27: Books, Newspapers, Online articles | L27: 4 | M27: 4 | N27: No | O27: No | P27: No | Q27: No | R27: No | S27: No | T27: No | U27: No | V27: No | W27: No | X27: No | Y27: No | Z27: nothing has changed overtime maybe a little bit | AA27: Yes | AB27: 2 | AC27: yes, 2010 | AD27: yes, 2010 | AE27: yes, mental health | AF27: alcohol | AG27: Yes | AH27: normal | AI27: Laptop | AJ27: am indoors | AK27: I understand
A28: 45856.467 | B28: 67e04f4402f278a9ccfe0f87 | C28: 34 | D28: female | E28: Doctoral degree | F28: English | H28: 5 | I28: 5 | J28: English | K28: Books, Magazines, Newspapers, Online articles, Social media | L28: 5 | M28: 4 | N28: No | O28: No | P28: No | Q28: No | R28: No | S28: No | T28: No | U28: No | V28: No | W28: No | X28: No | Y28: No | Z28: My reading habits have improved over time as my reading speed has increased | AA28: No | AB28: 3 | AC28: No | AD28: No | AE28: No | AF28: No | AG28: Yes | AI28: Desktop | AJ28: I am indoors | AK28: I understand
A29: 45856.505 | B29: 5bcbfa2832e46700016f1c1d | C29: 33 | D29: Female | E29: Associate's degree (2-years of college) | F29: English | H29: 5 | I29: 5 | J29: English | K29: Books, Magazines, Newspapers, Online articles, Social media | L29: 5 | M29: 5 | N29: No | O29: No | P29: No | Q29: No | R29: No | S29: No | T29: No | U29: No | V29: No | W29: No | X29: No | Y29: No | Z29: I've opened my mind to different genres of books | AA29: No | AB29: 4 | AC29: No | AD29: N/A | AE29: No | AF29: No | AG29: Yes | AH29: Glasses | AI29: Desktop | AJ29: Mid lighting room. Quiet | AK29: I understand
A30: 45856.518 | B30: 677c4861d510515568796dab | C30: 28 | D30: F | E30: Some college | F30: English | H30: 5 | I30: 5 | J30: English | K30: Books, Magazines, Newspapers, Online articles, Social media | L30: 5 | M30: 4 | N30: No | O30: No | P30: No | Q30: Yes | R30: No | S30: No | T30: No | U30: No | V30: Yes | W30: No | X30: No | Y30: No | Z30: I feel like I became slightly slower when reading texts and it became easier for me to mix up numbers occasionally. | AA30: No | AB30: 4 | AC30: ADHD | AD30: Yes, one year ago | AG30: No | AI30: Desktop | AJ30: I'm in a small office space with one window and natural light. | AK30: I understand
A31: 45856.526 | B31: 67e23f61d6642c6710f62686 | C31: 34 | D31: male | E31: Doctoral degree | F31: English | H31: 5 | I31: 5 | J31: English | K31: Online articles | L31: 4 | M31: 4 | N31: No | O31: No | P31: No | Q31: Yes | R31: No | S31: No | T31: Yes | U31: No | V31: No | W31: No | X31: No | Y31: No | Z31: I like reading | AA31: No | AB31: 4 | AG31: No | AI31: Desktop | AJ31: I am in a quite room sited on a chair. | AK31: I understand
A32: 45859.439 | B32: 682a50d2769e21e578e1c3d4 | C32: 19 | D32: male | E32: High school/GED | F32: English | H32: 5 | I32: 5 | J32: English | K32: Books, Magazines, Newspapers, Online articles, Social media | L32: 5 | M32: 5 | N32: No | O32: No | P32: No | Q32: No | R32: No | S32: Yes | T32: No | U32: No | V32: No | W32: No | X32: No | Y32: No | Z32: appreciated | AA32: No | AB32: 1 | AC32: No | AD32: No | AE32: No | AF32: No | AG32: No | AI32: Desktop | AJ32: I am indoors in an office | AK32: I understand
A33: 45859.439 | B33: 682a1996cd2cfa1f1160cb71 | C33: 42 | D33: Male | E33: Some college | F33: English | G33: 1 | H33: 5 | I33: 5 | J33: English | K33: Books, Magazines, Newspapers, Online articles, Social media | L33: 5 | M33: 4 | N33: No | O33: Yes | P33: No | Q33: No | R33: No | S33: No | T33: No | U33: No | V33: No | W33: No | X33: No | Y33: No | Z33: I read more often until I got better | AA33: Yes | AB33: 5 | AC33: ADHD | AD33: hyperactive-impulsive | AE33: Type 2 diabetes | AF33: no | AG33: Yes | AH33: glasses | AI33: Laptop | AJ33: indoors | AK33: I understand
A34: 45859.44 | B34: 5c508096f45b26000122f391 | C34: 36 | D34: female | E34: Associate's degree (2-years of college) | F34: English | H34: 5 | I34: 5 | J34: English | K34: Books, Magazines, Online articles | L34: 3 | M34: 3 | N34: No | O34: No | P34: No | Q34: Yes | R34: No | S34: No | T34: Yes | U34: No | V34: No | W34: No | X34: No | Y34: No | Z34: I am sure I had more time to read until I turned 30 and started working harder hours so not much time for leisure. | AA34: No | AB34: 4 | AC34: yes, ADHD | AD34: yes, ADHD, Last year | AE34: depression, | AF34: no | AG34: Yes | AH34: glasses | AI34: Desktop | AJ34: indoors, by a window and it is in the morning | AK34: I understand
A35: 45859.446 | B35: 67ed7edbe57ce7b9014a8400 | C35: 57 | D35: FEMALE | E35: Master's degree | F35: English | H35: 5 | I35: 5 | J35: English | K35: Books, Magazines, Newspapers, Online articles, Social media | L35: 5 | M35: 5 | N35: No | O35: No | P35: No | Q35: No | R35: No | S35: No | T35: No | U35: No | V35: No | W35: No | X35: No | Y35: No | Z35: It has improved in a positive manner | AA35: Yes | AB35: 1 | AC35: yes | AD35: Yes ADHD 5 YEARS | AE35: Yes Diabetes, 10 years ago | AF35: no | AG35: Yes | AH35: normal | AI35: Desktop | AJ35: indoors in a small quiet well lit room | AK35: I understand
A36: 45859.465 | B36: 67ef5d4cd8cc8b703fdf70f4 | C36: 45 | D36: Female | E36: Master's degree | F36: English | G36: spanish | H36: 5 | I36: 5 | J36: English | K36: Books, Magazines, Newspapers, Online articles, Social media | L36: 5 | M36: 5 | N36: No | O36: No | P36: No | Q36: No | R36: No | S36: No | T36: No | U36: No | V36: No | W36: No | X36: No | Y36: No | Z36: Sometime back as a kid ,I used to read a lot of fiction for fun. In school it became more of studying. These day I end up reading many articles and some short pieces. | AA36: No | AB36: 3 | AC36: NO | AD36: NO | AE36: NO | AF36: NO | AG36: Yes | AI36: Laptop | AJ36: Indoors | AK36: I understand
A37: 45859.473 | B37: 67548479896611f20a4da518 | C37: 64 | D37: Female | E37: Professional degree | F37: English | H37: 5 | I37: 4 | J37: English | K37: Books, Magazines, Online articles | L37: 5 | M37: 4 | N37: No | O37: No | P37: No | Q37: No | R37: No | S37: No | T37: No | U37: No | V37: Yes | W37: No | X37: Yes | Y37: No | Z37: My reading habits has changed but not in a negative way, I am still able to read fluently even with my age and Idon't encounter any major difficulties at all | AA37: No | AB37: 4 | AE37: I was diagnosed with diabetes 4 year ago | AF37: No I'm not | AG37: Yes | AH37: glasses | AI37: Desktop | AJ37: I'm in door and there is a little brightness in rhe room | AK37: I understand
A38: 45859.62 | B38: 5c47f0c82381060001bf7500 | C38: 29 | D38: female | E38: Some college | F38: English | G38: French | H38: 5 | I38: 5 | J38: English | K38: Books, Online articles, Social media | L38: 4 | M38: 4 | N38: No | O38: No | P38: No | Q38: No | R38: Yes | S38: No | T38: No | U38: No | V38: Yes | W38: Yes | X38: No | Y38: No | Z38: I've improved quite a bit after struggling for a long time but now I enjoy reading | AA38: No | AB38: 5 | AG38: Yes | AH38: glasses | AI38: Laptop | AJ38: I'm inside in a dimly lit room, sitting by a window | AK38: I understand
A39: 45859.622 | B39: 66c290bb20faa822520e73e3 | C39: 49 | D39: female | E39: High school/GED | F39: English | H39: 5 | I39: 5 | J39: English | K39: Books, Magazines, Newspapers, Online articles, Social media | L39: 4 | M39: 5 | N39: No | O39: Yes | P39: No | Q39: No | R39: No | S39: No | T39: No | U39: No | V39: Yes | W39: No | X39: Yes | Y39: No | Z39: They really haven't. I still read a lot, have for a lot of years. | AA39: No | AB39: 4 | AC39: 35 | AD39: no | AE39: no | AF39: no | AG39: Yes | AH39: glasses | AI39: Laptop | AJ39: Home, inside bright room natural light, large room | AK39: I understand
A40: 45859.622 | B40: 67886304e14dce87368e3688 | C40: 63 | D40: male | E40: High school/GED | F40: English | G40: none | H40: 5 | I40: 5 | J40: English | K40: Books, Magazines, Newspapers, Online articles, Social media | L40: 5 | M40: 5 | N40: No | O40: Yes | P40: No | Q40: No | R40: No | S40: No | T40: Yes | U40: No | V40: No | W40: No | X40: No | Y40: No | Z40: yes i read less | AA40: No | AB40: 1 | AC40: no | AD40: no | AE40: no | AF40: no | AG40: Yes | AH40: glasses | AI40: Laptop | AJ40: laying bed in a dark roon | AK40: I understand
...

Sheet dys_score
D1: =COUNTIF(D5:D862, ">12") -> 42
D3: https://outsidersoftware.co.uk/wp-content/uploads/2012/11/RevisedADOScreening.pdf | E3: 3 | F3: 3 | G3: 3 | H3: 3 | I3: 3 | J3: 2 | K3: 2 | L3: 2 | M3: 2 | N3: 2 | O3: 2 | P3: 3
A4: Timestamp | B4: Please enter your Prolific ID: | D4: SCORE | E4: When using the telephone, do you get the numbers mixed up when you dial? | F4: Is your spelling poor? | G4: When writing down dates, do you often make mistakes? | H4: Do you mix up dates and times and miss appointments? | I4: Do you find forms difficult and confusing? | J4: Do you find it difficult to take messages on the phone and pass them on correctly? | K4: Do you mix up bus numbers like 35 and 53? | L4: Do you find it difficult to say the months of the year forwards in a fluent manner? | M4: When you were at school, did you find it hard to learn the multiplication or times tables? | N4: Do you take longer than you should to read a page of a book? | O4: Do you find difficulty in telling left from right? | P4: Did you find it difficult to decide how to answer these questions?
A5: =Sheet1!A:A -> 45848.513 | B5: =Sheet1!B:B -> 614e0468bbbac16be38fa13f | D5: =SUMPRODUCT((E5:P5="Yes")*(E$3:P$3)) -> 13 | E5: =Sheet1!N:N -> Yes | F5: =Sheet1!O:O -> Yes | G5: =Sheet1!P:P -> No | H5: =Sheet1!Q:Q -> No | I5: =Sheet1!R:R -> No | J5: =Sheet1!S:S -> No | K5: =Sheet1!T:T -> No | L5: =Sheet1!U:U -> No | M5: =Sheet1!V:V -> Yes | N5: No | O5: =Sheet1!X:X -> Yes | P5: =Sheet1!Y:Y -> Yes
A6: =Sheet1!A:A -> 45848.514 | B6: =Sheet1!B:B -> 63d1125c54e8148f4cd30a65 | D6: =SUMPRODUCT((E6:P6="Yes")*(E$3:P$3)) -> 3 | E6: =Sheet1!N:N -> No | F6: =Sheet1!O:O -> Yes | G6: =Sheet1!P:P -> No | H6: =Sheet1!Q:Q -> No | I6: =Sheet1!R:R -> No | J6: =Sheet1!S:S -> No | K6: =Sheet1!T:T -> No | L6: =Sheet1!U:U -> No | M6: =Sheet1!V:V -> No | N6: No | O6: =Sheet1!X:X -> No | P6: =Sheet1!Y:Y -> No
A7: =Sheet1!A:A -> 45853.835 | B7: =Sheet1!B:B -> 6664d3b710bb2abd191e1b64 | D7: =SUMPRODUCT((E7:P7="Yes")*(E$3:P$3)) -> 0 | E7: =Sheet1!N:N -> No | F7: =Sheet1!O:O -> No | G7: =Sheet1!P:P -> No | H7: =Sheet1!Q:Q -> No | I7: =Sheet1!R:R -> No | J7: =Sheet1!S:S -> No | K7: =Sheet1!T:T -> No | L7: =Sheet1!U:U -> No | M7: =Sheet1!V:V -> No | N7: No | O7: =Sheet1!X:X -> No | P7: =Sheet1!Y:Y -> No
A8: =Sheet1!A:A -> 45853.839 | B8: =Sheet1!B:B -> 676cf85a261dedbddea3e240 | D8: =SUMPRODUCT((E8:P8="Yes")*(E$3:P$3)) -> 0 | E8: =Sheet1!N:N -> No | F8: =Sheet1!O:O -> No | G8: =Sheet1!P:P -> No | H8: =Sheet1!Q:Q -> No | I8: =Sheet1!R:R -> No | J8: =Sheet1!S:S -> No | K8: =Sheet1!T:T -> No | L8: =Sheet1!U:U -> No | M8: =Sheet1!V:V -> No | N8: No | O8: =Sheet1!X:X -> No | P8: =Sheet1!Y:Y -> No
A9: =Sheet1!A:A -> 45853.85 | B9: =Sheet1!B:B -> 668a9e53e7690b3b64d48e92 | D9: =SUMPRODUCT((E9:P9="Yes")*(E$3:P$3)) -> 0 | E9: =Sheet1!N:N -> No | F9: =Sheet1!O:O -> No | G9: =Sheet1!P:P -> No | H9: =Sheet1!Q:Q -> No | I9: =Sheet1!R:R -> No | J9: =Sheet1!S:S -> No | K9: =Sheet1!T:T -> No | L9: =Sheet1!U:U -> No | M9: =Sheet1!V:V -> No | N9: No | O9: =Sheet1!X:X -> No | P9: =Sheet1!Y:Y -> No
A10: =Sheet1!A:A -> 45853.857 | B10: =Sheet1!B:B -> 610508c09d61c098f072605b | D10: =SUMPRODUCT((E10:P10="Yes")*(E$3:P$3)) -> 0 | E10: =Sheet1!N:N -> No | F10: =Sheet1!O:O -> No | G10: =Sheet1!P:P -> No | H10: =Sheet1!Q:Q -> No | I10: =Sheet1!R:R -> No | J10: =Sheet1!S:S -> No | K10: =Sheet1!T:T -> No | L10: =Sheet1!U:U -> No | M10: =Sheet1!V:V -> No | N10: No | O10: =Sheet1!X:X -> No | P10: =Sheet1!Y:Y -> No
A11: =Sheet1!A:A -> 45853.877 | B11: =Sheet1!B:B -> 65ee224fc6146bbd065a8ae0 | D11: =SUMPRODUCT((E11:P11="Yes")*(E$3:P$3)) -> 0 | E11: =Sheet1!N:N -> No | F11: =Sheet1!O:O -> No | G11: =Sheet1!P:P -> No | H11: =Sheet1!Q:Q -> No | I11: =Sheet1!R:R -> No | J11: =Sheet1!S:S -> No | K11: =Sheet1!T:T -> No | L11: =Sheet1!U:U -> No | M11: =Sheet1!V:V -> No | N11: No | O11: =Sheet1!X:X -> No | P11: =Sheet1!Y:Y -> No
A12: =Sheet1!A:A -> 45855.656 | B12: =Sheet1!B:B -> 66eddcfe67e927db6f0a4768 | D12: =SUMPRODUCT((E12:P12="Yes")*(E$3:P$3)) -> 10 | E12: =Sheet1!N:N -> Yes | F12: =Sheet1!O:O -> No | G12: =Sheet1!P:P -> No | H12: =Sheet1!Q:Q -> No | I12: =Sheet1!R:R -> Yes | J12: =Sheet1!S:S -> Yes | K12: =Sheet1!T:T -> Yes | L12: =Sheet1!U:U -> No | M12: =Sheet1!V:V -> No | N12: No | O12: =Sheet1!X:X -> No | P12: =Sheet1!Y:Y -> No
A13: =Sheet1!A:A -> 45855.658 | B13: =Sheet1!B:B -> 6108295fdd0270d7544b5a8a | D13: =SUMPRODUCT((E13:P13="Yes")*(E$3:P$3)) -> 28 | E13: =Sheet1!N:N -> Yes | F13: =Sheet1!O:O -> Yes | G13: =Sheet1!P:P -> Yes | H13: =Sheet1!Q:Q -> Yes | I13: =Sheet1!R:R -> Yes | J13: =Sheet1!S:S -> Yes | K13: =Sheet1!T:T -> Yes | L13: =Sheet1!U:U -> Yes | M13: =Sheet1!V:V -> Yes | N13: No | O13: =Sheet1!X:X -> Yes | P13: =Sheet1!Y:Y -> Yes
A14: =Sheet1!A:A -> 45855.659 | B14: =Sheet1!B:B -> 67842c60c9cba1e154a69bbd | D14: =SUMPRODUCT((E14:P14="Yes")*(E$3:P$3)) -> 12 | E14: =Sheet1!N:N -> Yes | F14: =Sheet1!O:O -> No | G14: =Sheet1!P:P -> No | H14: =Sheet1!Q:Q -> Yes | I14: =Sheet1!R:R -> No | J14: =Sheet1!S:S -> No | K14: =Sheet1!T:T -> Yes | L14: =Sheet1!U:U -> Yes | M14: =Sheet1!V:V -> Yes | N14: No | O14: =Sheet1!X:X -> No | P14: =Sheet1!Y:Y -> No
A15: =Sheet1!A:A -> 45855.66 | B15: =Sheet1!B:B -> 67e99ec5ac9317593a3fd76b | D15: =SUMPRODUCT((E15:P15="Yes")*(E$3:P$3)) -> 0 | E15: =Sheet1!N:N -> No | F15: =Sheet1!O:O -> No | G15: =Sheet1!P:P -> No | H15: =Sheet1!Q:Q -> No | I15: =Sheet1!R:R -> No | J15: =Sheet1!S:S -> No | K15: =Sheet1!T:T -> No | L15: =Sheet1!U:U -> No | M15: =Sheet1!V:V -> No | N15: No | O15: =Sheet1!X:X -> No | P15: =Sheet1!Y:Y -> No
A16: =Sheet1!A:A -> 45855.661 | B16: =Sheet1!B:B -> 67e08140fcb66593f11b6e8e | D16: =SUMPRODUCT((E16:P16="Yes")*(E$3:P$3)) -> 5 | E16: =Sheet1!N:N -> No | F16: =Sheet1!O:O -> No | G16: =Sheet1!P:P -> Yes | H16: =Sheet1!Q:Q -> No | I16: =Sheet1!R:R -> No | J16: =Sheet1!S:S -> No | K16: =Sheet1!T:T -> No | L16: =Sheet1!U:U -> No | M16: =Sheet1!V:V -> Yes | N16: No | O16: =Sheet1!X:X -> No | P16: =Sheet1!Y:Y -> No
... A311: =Sheet1!A:A | B311: =Sheet1!B:B -> 4D90715B030E42DAA62779F3 | D311: =SUMPRODUCT((E311:P311="Yes")*(E$3:P$3)) -> 0 | E311: =Sheet1!N:N | F311: =Sheet1!O:O | G311: =Sheet1!P:P | H311: =Sheet1!Q:Q | I311: =Sheet1!R:R | J311: =Sheet1!S:S | K311: =Sheet1!T:T | L311: =Sheet1!U:U | M311: =Sheet1!V:V | N311: No | O311: =Sheet1!X:X | P311: =Sheet1!Y:Y
